Workbook

Sheet Телефония
A1: http://yealink.review.ipmatika.kz/ | H1: ПРАВСИМВ(Подбор!R1C7;21) | I1: ПРАВСИМВ(Подбор!R1C7;19)
A2: Наименование товара | B2: Артикул | C2: РРЦ | F2: Цена Сайт | G2: . | H2: Я бы купил!
A3: 1. SIP-телефоны
A4: Yealink SIP-T30 SIP-телефон, 1 линия, С БП замена T19 | B4: SIP-T30 | C4: 27960 | F4: =C4*0.93 -> 26002.8 | H4: add
A5: Yealink SIP-T30P SIP-телефон, 1 линия, Poe c БП замена T19P | B5: SIP-T30P | C5: 31370 | F5: =C5*0.93 -> 29174.1 | H5: add
A6: Yealink SIP-T31 SIP-телефон, 2 линии, с БП замена T21 | B6: SIP-T31 | C6: 29810 | F6: =C6*0.93 -> 27723.3 | H6: add
A7: Yealink SIP-T31P SIP-телефон, 2 линии, Poe, с БП замена T21P | B7: SIP-T31P | C7: 35000 | F7: =C7*0.93 -> 32550 | H7: add
A8: Yealink SIP-T31P, цвет светло-серый, 2 аккаунта, PoE | B8: SIP-T31P Light Gray | C8: 42120 | F8: =C8*0.93 -> 39171.6 | H8: add
A9: Yealink SIP-T31G SIP-телефон, 2 линии, PoE, GigE, с БП замена T23G | B9: SIP-T31G | C9: 40170 | F9: =C9*0.93 -> 37358.1 | H9: add
A10: Yealink SIP-T33G,4 линии,цветной экран, PoE, GigE, с БП замена T40G | B10: SIP-T33G | C10: 52530 | F10: =C10*0.93 -> 48852.9 | H10: add
A11: Yealink SIP-T31W, 2 аккаунта, Wi-Fi, PoE | B11: SIP-T31W | C11: 45360 | F11: =C11*0.93 -> 42184.8 | H11: add
A12: Yealink SIP-T34W, 4 аккаунта, Wi-Fi, USB, цветной экран, PoE, GigE | B12: SIP-T34W | C12: 61880 | F12: =C12*0.93 -> 57548.4 | H12: add
A13: Yealink SIP-T42G,3 аккаунта,BLF,PoE, GigE, без БП | B13: SIP-T42G sale | C13: 63420 | F13: =C13*0.93 -> 58980.6 | H13: add
A14: Yealink SIP-T43U (12 аккаунтов, 2 порта USB, BLF, PoE, GigE) без БП | B14: SIP-T43U | C14: 85360 | F14: =C14*0.93 -> 79384.8 | H14: add
A15: Yealink SIP-T44U, 12 аккаунтов, 2 порта USB, цветной экран, BLF, PoE, GigE, без БП | B15: SIP-T44U | C15: 93180 | F15: =C15*0.93 -> 86657.4 | H15: add
... A26: Yealink MP50 USB-телефон, Bluetooth, сенсорный экран | B26: MP50 | C26: 105370 | F26: =C26*0.93 -> 97994.1 | H26: add
A27: Yealink SIP-T73U, 12 аккаунтов, 2,8" цветной экран, порт USB, BLF, PoE, GigE, без БП | B27: SIP-T73U | C27: 88480 | F27: =C27*0.93 -> 82286.4
A28: Yealink SIP-T73W, 12 аккаунтов, Wi-Fi, 2,8" цветной экран, порт USB, BLF, PoE, GigE, без БП | B28: SIP-T73W | C28: 100060 | F28: =C28*0.93 -> 93055.8
A29: Yealink SIP-T74U, 16 аккаунтов, 4,3" цветной экран, порт USB, BLF, PoE, GigE, без БП | B29: SIP-T74U | C29: 140760 | F29: =C29*0.93 -> 130906.8
A30: Yealink SIP-T74W, 16 аккаунтов, Wi-Fi, 4,3" цветной экран, порт USB, BLF, PoE, GigE, без БП | B30: SIP-T74W | C30: 154830 | F30: =C30*0.93 -> 143991.9
A31: Yealink SIP-T77U, 7" цветной сенсорный экран, 2 порта USB, 16 аккаунтов, BLF, PoE, GigE, без БП | B31: SIP-T77U | C31: 192970 | F31: =C31*0.93 -> 179462.1
A32: Yealink AX83H, экран 2.4", Wi-Fi 6, виброоповещение, Bluetooth, 3.5 mm, Type-C, SNC, звук HD | B32: AX83H | C32: 90010 | F32: =C32*0.93 -> 83709.3
A33: Yealink AX86R, экран 2.4", Wi-Fi 6, IP67, Alarm, виброоповещение, Bluetooth, 3.5 mm, Type-C, SNC, звук HD | B33: AX86R | C33: 142980 | F33: =C33*0.93 -> 132971.4
A34: Yealink W56H DECT SIP-трубка | B34: W56H | C34: 70360 | F34: =C34*0.93 -> 65434.8 | H34: add
A35: Yealink W59R DECT SIP-трубка | B35: W59R | C35: 124080 | F35: =C35*0.93 -> 115394.4 | H35: add
A36: Yealink W57R, степень защиты IP54, HD звук, вибросигнал, FNR, быстрая зарядка, для W70B/W80B/W90B | B36: W57R | C36: 112710 | F36: =C36*0.93 -> 104820.3 | H36: add
A37: Yealink W70B DECT, базовая станция, до 10 SIP-аккаунтов, до 10 трубок на базу, до 20 одновременных вызовов | B37: W70B | C37: 54110 | F37: =C37*0.93 -> 50322.3 | H37: add
A38: Yealink W74H, экран 1.8", виброоповещение, FNR, BT, 3.5 mm, для W70B/W71P/W73P/W74P/W76P/W79P/W75/W80/W90 | B38: W74H | C38: 68810 | F38: =C38*0.93 -> 63993.3 | H38: add
A39: Yealink W73H DECT SIP-трубка для W70B/W73P/W76P//W79P/W80B/W90B | B39: W73H | C39: 61930 | F39: =C39*0.93 -> 57594.9 | H39: add
A40: Yealink W71H, экран 1.8", FNR, для W70B/W71P/W73P/W74P/W76P/W79P/W75/W80/W90 | B40: W71H | C40: 49910 | F40: =C40*0.93 -> 46416.3 | H40: add
A41: Yealink W78H, HD звук, экран 2.4", виброоповещение, 3.5 мм, для W70B/W80B/W90B | B41: W78H | C41: 93050 | F41: =C41*0.93 -> 86536.5 | H41: add
A42: Yealink W79P DECT (база W70B +трубка W59R ) до 10 SIP-аккаунтов, до 10 трубок на базу, до 20 одноврем. Вызовов | B42: W79P | C42: 173970 | F42: =C42*0.93 -> 161792.1 | H42: add
A43: Yealink W78P (база W70B+трубка W78H) до 10 SIP-аккаунтов, до 10 трубок на базу, до 20 одновременных вызовов | B43: W78P | C43: 132370 | F43: =C43*0.93 -> 123104.1 | H43: add
A44: Yealink W77P (база W70B+трубка W57R) до 10 SIP-аккаунтов, до 10 трубок на базу, до 20 одновременных вызовов | B44: W77P | C44: 158580 | F44: =C44*0.93 -> 147479.4 | H44: add
A45: Yealink W76P DECT (база W70B+трубка W56H) до 10 SIP-аккаунтов, до 10 трубок на базу, до 20 одноврем. вызовов | B45: W76P | C45: 111290 | F45: =C45*0.93 -> 103499.7 | H45: add
... A70: Yealink SP96 with Dongle USB-C/A, USB, Bluetooth, Экран, встроенная батарея, 6 встроенных микрофонов | B70: SP96 with Dongle USB-C/A | C70: 134080 | F70: =C70*0.93 -> 124694.4 | H70: add
A71: Телефоны для Teams/Skype for Business | F71: =C71*0.93 -> 0
A72: Yealink MP50 USB-телефон, Bluetooth, сенсорный экран | B72: MP50 | C72: 105370 | F72: =C72*0.93 -> 97994.1 | H72: add
A73: Yealink SIP MP54, Teams/Skype for Business, цветной сенсорный экран, Звук Optima HD, USB, PoE, GigE, без БП | B73: MP54-TEAMS | C73: 218260 | F73: =C73*0.93 -> 202981.8 | H73: add
A74: Yealink SIP-MP56, Teams/Skype for Business, цветной сенсорный экран, PoE, GigE, без БП | B74: MP56-Teams | C74: 276460 | F74: =C74*0.93 -> 257107.8 | H74: add
...

Sheet Yeastar
A2: Артикул | B2: Краткое описание | C2: РРЦ | D2: Сайт Цена
A3: P - Серия
A4: P520 | B4: IP-АТС до 20 абонентов и до 10 одновременных вызовов позволяет подключать аналоговые линии/телефоны, линии BRI и GSM-линию посредством дополнительных модулей, поддерживает протоколы MFC R2, SS7, FXO, FXS, GSM, BRI, WCDMA(3G), LTE(4G) | C4: 314050 | D4: =C4*0.93 -> 292066.5
A5: P550 | B5: IP-АТС до 50 абонентов и до 25 одновременных вызовов позволяет подключать аналоговые линии/телефоны, линии BRI и GSM-линию посредством дополнительных модулей, поддерживает протоколы MFC R2, SS7, FXO, FXS, GSM, BRI, WCDMA(3G), LTE(4G) | C5: 615450 | D5: =C5*0.93 -> 572368.5
A6: P560 | B6: IP-АТС на 100 абонентов и 30 одновременных вызовов позволяет подключать аналоговые линии/телефоны, линии BRI и GSM-линию посредством дополнительных модулей, поддерживает протоколы MFC R2, SS7, FXO, FXS, GSM, BRI, WCDMA(3G), LTE(4G) | C6: 813450 | D6: =C6*0.93 -> 756508.5
A7: P570 | B7: IP-АТС на 300 абонентов и 60 одновременных вызовов позволяет подключать аналоговые линии/телефоны, линии BRI/PRI и GSM-линии посредством дополнительных модулей, поддерживает протоколы MFC R2, SS7, FXO, FXS, GSM, BRI, PRI, WCDMA(3G), LTE(4G), с помощью модуля D30 расширяется до 200 пользователей и 60 одновременных вызовов | C7: 1658800 | D7: =C7*0.93 -> 1542684
A8: S - Серия
A9: S20 | B9: IP-АТС до 20 абонентов и до 10 одновременных вызовов позволяет подключать аналоговые линии/телефоны, линии BRI и GSM-линию посредством дополнительных модулей, поддерживает протоколы MFC R2, SS7, FXO, FXS, GSM, BRI, WCDMA(3G), LTE(4G) | C9: 276100 | D9: =C9*0.93 -> 256773
A10: S50 | B10: IP-АТС на 50 абонентов и 25 одновременных вызовов позволяет подключать аналоговые линии/телефоны, линии BRI и GSM-линию посредством дополнительных модулей, поддерживает протоколы MFC R2, SS7, FXO, FXS, GSM, BRI, WCDMA(3G), LTE(4G) | C10: 520850 | D10: =C10*0.93 -> 484390.5
A11: S100 | B11: IP-АТС на 100 абонентов и 30 одновременных вызовов позволяет подключать аналоговые линии/телефоны, линии BRI и GSM-линию посредством дополнительных модулей, поддерживает протоколы MFC R2, SS7, FXO, FXS, GSM, BRI, WCDMA(3G), LTE(4G) | C11: 691820 | D11: =C11*0.93 -> 643392.6
A12: Модули для АТС
A13: EX08 | B13: Плата расширения для телефонных станций Yeastar S-серии (S-100 и S-300) На плату может быть установлено до 4-х модулей S2, O2, SO, BRI, GSM, WCDMA и LTE. | C13: 56100 | D13: =C13*0.93 -> 52173
A14: EX30 | B14: Плата расширения для телефонных станций Yeastar S-серии (S-100 и S-300) Поддерживает подключение одного интерфейса E1/T1 | C14: 486200 | D14: =C14*0.93 -> 452166
A15: D30 Card | B15: DSP-модуль для телефонных станций Yeastar S-серии (S100 /S300) один модуль добавляет возможности расширения до 100 пользователей и 30 одновременных вызовов. | C15: 163350 | D15: =C15*0.93 -> 151915.5
A16: O2 | B16: Модуль для подключения 2-х FXO телефонных линий Предназначен для работы со всеми IP-АТС Yeastar. | C16: 64900 | D16: =C16*0.93 -> 60357
A17: S2 | B17: Модуль для подключения 2-х FXS телефонных линий Предназначен для работы со всеми IP-АТС Yeastar. | C17: 57750 | D17: =C17*0.93 -> 53707.5
A18: SO | B18: Модуль для подключения одной FXS и одной FXO линии Переключается в режим «Моста» при неработоспособности системы, соединяя напрямую аналоговый телефон с внешней телефонной линией. Предназначен для работы со всеми IP-АТС Yeastar. | C18: 67100 | D18: =C18*0.93 -> 62403
A19: GSM | B19: Модуль для подключения одного GSM-канала (GSM 850/900/1800/1900МГц ). Предназначен для работы со всеми IP-АТС Yeastar. | C19: 95150 | D19: =C19*0.93 -> 88489.5
A20: UMTS | B20: Модуль для подключения одного UMTS-канала (UMTS 900/2100МГц или 850/2100МГц или 850/1900МГц). Предназначен для работы со всеми IP-АТС Yeastar. | C20: 154050 | D20: =C20*0.93 -> 143266.5
A21: LTE | B21: Модуль для подключения одной LTE линии, позволяет передавать VoIP-данные через сети 4G для подключения к VoIP-операторам по протоколу SIP | C21: 219450 | D21: =C21*0.93 -> 204088.5
A22: B2 | B22: Модуль для подключения двух линий BRI предназначен для работы со всеми IP-АТС Yeastar | C22: 110200 | D22: =C22*0.93 -> 102486
A23: GSM - шлюзы
A24: TG100 | B24: VoIP-GSM-шлюз с поддержкой 1 GSM-линии 850/900/1800/1900 МГц | C24: 87050 | D24: =C24*0.93 -> 80956.5
A25: TG200 | B25: VoIP-GSM-шлюз с поддержкой 2 GSM-линий 850/900/1800/1900 МГц | C25: 174710 | D25: =C25*0.93 -> 162480.3
A26: TG400 | B26: VoIP-GSM-шлюз с поддержкой 4 GSM-линий 850/900/1800/1900 МГц | C26: 330290 | D26: =C26*0.93 -> 307169.7
A27: TG800 | B27: VoIP-GSM-шлюз с поддержкой 8 GSM-линий 850/900/1800/1900 МГц | C27: 598250 | D27: =C27*0.93 -> 556372.5
A28: TG1600/16 | B28: VoIP-GSM-шлюз с поддержкой 16 GSM-линий 850/900/1800/1900 МГц ( 8 GSM-линий 850/900/1800/1900 в комплекте ) | C28: 1234780 | D28: =C28*0.93 -> 1148345.4
A29: FXS/FXO - шлюзы
A30: TA100 | B30: VoIP-FXS-шлюз с поддержкой 1 FXS-линии | C30: 22000 | D30: =C30*0.93 -> 20460
A31: TA200 | B31: VoIP-FXS-шлюз с поддержкой 2 FXS-линий | C31: 32090 | D31: =C31*0.93 -> 29843.7
A32: TA400 | B32: VoIP-FXS-шлюз с поддержкой 4 FXS-линий | C32: 73860 | D32: =C32*0.93 -> 68689.8
A33: TA800 | B33: VoIP-FXS-шлюз с поддержкой 8 FXS-линий | C33: 122900 | D33: =C33*0.93 -> 114297
A34: TA1600 | B34: VoIP-FXS-шлюз с поддержкой 16 FXS-линий | C34: 304440 | D34: =C34*0.93 -> 283129.2
A35: TA2400 | B35: VoIP-FXS-шлюз с поддержкой 24 FXS-линий | C35: 378740 | D35: =C35*0.93 -> 352228.2
A36: TA3200 | B36: VoIP-FXS-шлюз с поддержкой 32 FXS-линий | C36: 453730 | D36: =C36*0.93 -> 421968.9
A37: TA410 | B37: VoIP-FXS-шлюз с поддержкой 4 FXO-линий | C37: 134570 | D37: =C37*0.93 -> 125150.1
A38: TA810 | B38: VoIP-FXS-шлюз с поддержкой 8 FXO-линий | C38: 230560 | D38: =C38*0.93 -> 214420.8
A39: TA1610 | B39: VoIP-FXS-шлюз с поддержкой 16 FXO-линий | C39: 489500 | D39: =C39*0.93 -> 455235
A40: ISDN - шлюзы
A41: TE100 | B41: VoIP-PRI шлюз на 1 порт (E1/T1), поддерживающий до 30 одновременных вызовов | C41: 474070 | D41: =C41*0.93 -> 440885.1
...

Sheet Сетевое
A1: URL | B1: Артикул | C1: Описание | D1: Цена | E1: Дилер
F2: Status
A3: https://ipmatika.kz/products/lte-routery/ | B3: LTE Роутеры
A4: https://ipmatika.kz/products/lte-routery/wi-tek-wi-lte110-o-v2/ | B4: WI-LTE110-O v2 | C4: WI-LTE110-O Outdoor LTE роутер, Cloud | D4: =IFERROR(VLOOKUP($B4,Подбор[#All],4,0),"") -> 46430 | E4: =IFERROR(VLOOKUP($B4,Подбор[#All],5,0),"") -> 37147.55 | F4: =IFERROR(VLOOKUP($B4,Подбор[#All],19,0),"")
A5: https://ipmatika.kz/products/lte-routery/wi-tek-wi-lte113-o/ | B5: WI-LTE113-O | C5: WI-LTE113-O Внешний LTE роутер | D5: =IFERROR(VLOOKUP($B5,Подбор[#All],4,0),"") -> 159190 | E5: =IFERROR(VLOOKUP($B5,Подбор[#All],5,0),"") -> 127352.77 | F5: =IFERROR(VLOOKUP($B5,Подбор[#All],19,0),"")
A6: https://ipmatika.kz/products/lte-routery/wi-tek-wi-lte115-o-v2/ | B6: WI-LTE115-O v2 | C6: WI-LTE115-O Внешний LTE роутер, Cloud | D6: =IFERROR(VLOOKUP($B6,Подбор[#All],4,0),"") -> 46430 | E6: =IFERROR(VLOOKUP($B6,Подбор[#All],5,0),"") -> 37147.55 | F6: =IFERROR(VLOOKUP($B6,Подбор[#All],19,0),"") -> EOL
A7: https://ipmatika.kz/products/lte-routery/wi-tek-wi-lte117-o-v2/ | B7: WI-LTE117-O v2 | C7: WI-LTE117-O v2 Внешний LTE роутер | D7: =IFERROR(VLOOKUP($B7,Подбор[#All],4,0),"") -> 51740 | E7: =IFERROR(VLOOKUP($B7,Подбор[#All],5,0),"") -> 41390.25 | F7: =IFERROR(VLOOKUP($B7,Подбор[#All],19,0),"")
B8: PON-оборудование | F8: =IFERROR(VLOOKUP($B8,Подбор[#All],19,0),"")
B9: WI-POL308G-P | C9: WI-POL308G-P, управляемый GPON MDU 8*GE PoE + 1*2,5G GPON SC | D9: =IFERROR(VLOOKUP($B9,Подбор[#All],4,0),"") -> 92860 | E9: =IFERROR(VLOOKUP($B9,Подбор[#All],5,0),"") -> 74287.125 | F9: =IFERROR(VLOOKUP($B9,Подбор[#All],19,0),"") -> Под заказ
B10: WI-POL5800-08 | C10: WI-POL5800-08, Управляемый коммутатор GPON OLT 8*GPON SC+4*10G SFP+4*GE | D10: =IFERROR(VLOOKUP($B10,Подбор[#All],4,0),"") -> 1193950 | E10: =IFERROR(VLOOKUP($B10,Подбор[#All],5,0),"") -> 955157.78 | F10: =IFERROR(VLOOKUP($B10,Подбор[#All],19,0),"") -> Под заказ
A11: https://ipmatika.kz/products/wifi-mosty/ | B11: WiFi мосты | F11: =IFERROR(VLOOKUP($B11,Подбор[#All],19,0),"")
A12: https://ipmatika.kz/products/wifi-mosty/wi-tek-wi-cpe110-kit/ | B12: WI-CPE110-KIT | C12: WI-CPE110-KIT комплект из двух преднастроенных точек доступа, 802.11b/g/n, 2.4ГГц, до 300Мбит/с | D12: =IFERROR(VLOOKUP($B12,Подбор[#All],4,0),"") -> 33170 | E12: =IFERROR(VLOOKUP($B12,Подбор[#All],5,0),"") -> 26532.825 | F12: =IFERROR(VLOOKUP($B12,Подбор[#All],19,0),"")
A13: https://ipmatika.kz/products/wifi-mosty/wi-tek-wi-cpe110-kit/ | B13: WI-CPE110-KIT v2 | C13: WI-CPE110-KIT комплект из двух преднастроенных точек доступа, 802.11b/g/n, 2.4ГГц, до 300Мбит/с | D13: =IFERROR(VLOOKUP($B13,Подбор[#All],4,0),"") -> 44000 | E13: =IFERROR(VLOOKUP($B13,Подбор[#All],5,0),"") | F13: =IFERROR(VLOOKUP($B13,Подбор[#All],19,0),"") -> NEW
A14: https://ipmatika.kz/products/wifi-mosty/wi-tek-wi-cpe111-kit-v2/ | B14: WI-CPE111-KIT V2 | C14: WI-CPE111-KIT комплект из двух преднастроенных точек доступа 802.11b/g/n 2,4ГГц до 300Мбит/с, Cloud | D14: =IFERROR(VLOOKUP($B14,Подбор[#All],4,0),"") -> 54390 | E14: =IFERROR(VLOOKUP($B14,Подбор[#All],5,0),"") -> 43511.6 | F14: =IFERROR(VLOOKUP($B14,Подбор[#All],19,0),"") -> EOL
A15: https://ipmatika.kz/products/wifi-mosty/wi-tek-wi-cpe511h-kit/ | B15: WI-CPE511H-KIT | C15: WI-CPE511H-KIT комплект из двух преднастроенных точек доступа, 802.11a/n, 5ГГц, до 900Мбит/с | D15: =IFERROR(VLOOKUP($B15,Подбор[#All],4,0),"") -> 59690 | E15: =IFERROR(VLOOKUP($B15,Подбор[#All],5,0),"") -> 47754.3 | F15: =IFERROR(VLOOKUP($B15,Подбор[#All],19,0),"")
A16: https://ipmatika.kz/products/wifi-mosty/wi-tek-wi-cpe513p-kit-v3/ | B16: WI-CPE513P-KIT v3 | C16: WI-CPE513P-KIT комплект из двух преднастроенных точек доступа 802.11a/n, 5ГГц, 2 LAN, PoE, Cloud | D16: 59260 | E16: 47550 | F16: Акция
A17: https://ipmatika.kz/products/wifi-mosty/wi-tek-wi-cpe515h-kit/ | B17: WI-CPE515H-KIT | C17: WI-CPE515H-KIT комплект из двух преднастроенных точек доступа наружная 802.11a/n 5ГГц до 300Мбит/c | D17: =IFERROR(VLOOKUP($B17,Подбор[#All],4,0),"") -> 91530 | E17: =IFERROR(VLOOKUP($B17,Подбор[#All],5,0),"") -> 73226.45 | F17: =IFERROR(VLOOKUP($B17,Подбор[#All],19,0),"") -> EOL
A18: https://ipmatika.kz/products/wifi-mosty/wi-tek-wi-cpe800-kit-v3/ | B18: WI-CPE800-KIT v3 | C18: WI-CPE800-KIT комплект из двух преднастроенных точек доступа, 802.11a/n, 5ГГц, до 867Мбит/с | D18: =IFERROR(VLOOKUP($B18,Подбор[#All],4,0),"") -> 112760 | E18: =IFERROR(VLOOKUP($B18,Подбор[#All],5,0),"") -> 90205.225 | F18: =IFERROR(VLOOKUP($B18,Подбор[#All],19,0),"") -> NEW
A19: https://ipmatika.kz/products/wifi-mosty/wi-tek-wi-cpe821/ | B19: WI-CPE821 | C19: WI-CPE821, Точка доступа наружная 360гр 802.11a/n 5,8Ггц до 867Мбит/c | D19: =IFERROR(VLOOKUP($B19,Подбор[#All],4,0),"") -> 145920 | E19: =IFERROR(VLOOKUP($B19,Подбор[#All],5,0),"") -> 116738.05 | F19: =IFERROR(VLOOKUP($B19,Подбор[#All],19,0),"")
A20: https://ipmatika.kz/products/wifi-smb/ | B20: WiFi точки доступа | F20: =IFERROR(VLOOKUP($B20,Подбор[#All],19,0),"")
A21: https://ipmatika.kz/products/wifi-smb/wi-tek-wi-ac105p-v2/ | B21: WI-AC105P v2 | C21: WI-AC105P Контроллер WiFi | D21: =IFERROR(VLOOKUP($B21,Подбор[#All],4,0),"") -> 46430 | E21: =IFERROR(VLOOKUP($B21,Подбор[#All],5,0),"") -> 37147.55 | F21: =IFERROR(VLOOKUP($B21,Подбор[#All],19,0),"")
A22: https://ipmatika.kz/products/wifi-smb/wi-tek-wi-ac108p-v2/ | B22: WI-AC108P v2 | C22: WI-AC108P Контроллер WiFi | D22: =IFERROR(VLOOKUP($B22,Подбор[#All],4,0),"") -> 79600 | E22: =IFERROR(VLOOKUP($B22,Подбор[#All],5,0),"") -> 63680.375 | F22: =IFERROR(VLOOKUP($B22,Подбор[#All],19,0),"")
A23: https://ipmatika.kz/products/wifi-smb/wi-tek-wi-ac150/ | B23: WI-AC150 | C23: WI-AC150 Контроллер WiFi | D23: =IFERROR(VLOOKUP($B23,Подбор[#All],4,0),"") -> 66330 | E23: =IFERROR(VLOOKUP($B23,Подбор[#All],5,0),"") -> 53065.65 | F23: =IFERROR(VLOOKUP($B23,Подбор[#All],19,0),"")
A24: https://ipmatika.kz/products/wifi-smb/wi-tek-wi-ac50/ | B24: WI-AC50 | C24: WI-AC50 Контроллер WiFi | D24: =IFERROR(VLOOKUP($B24,Подбор[#All],4,0),"") -> 23220 | E24: =IFERROR(VLOOKUP($B24,Подбор[#All],5,0),"") -> 18573.775 | F24: =IFERROR(VLOOKUP($B24,Подбор[#All],19,0),"") -> EOL
A25: https://ipmatika.kz/products/wifi-smb/wi-tek-wi-ac500/ | B25: WI-AC500 | C25: WI-AC500 Контроллер WiFi | D25: =IFERROR(VLOOKUP($B25,Подбор[#All],4,0),"") -> 331650 | E25: =IFERROR(VLOOKUP($B25,Подбор[#All],5,0),"") -> 265320.27 | F25: =IFERROR(VLOOKUP($B25,Подбор[#All],19,0),"") -> Под заказ
A26: https://ipmatika.kz/products/accessories/wi-tek-wi-aod6/ | B26: WI-AODB6 | C26: WI-AODB6, Антенна всенаправленная двухдиапазонная 2,4/5 ГГц (6dBi), type-N | D26: =IFERROR(VLOOKUP($B26,Подбор[#All],4,0),"") -> 9290 | E26: =IFERROR(VLOOKUP($B26,Подбор[#All],5,0),"") -> 7432.7 | F26: =IFERROR(VLOOKUP($B26,Подбор[#All],19,0),"") -> EOL
A27: https://ipmatika.kz/products/wifi-smb/wi-tek-wi-ap210-lite/ | B27: WI-AP210-Lite | C27: WI-AP210-Lite Точка доступа c поддержкой PoE, Wi-Fi 4 (802.11a/b/g/n) | D27: =IFERROR(VLOOKUP($B27,Подбор[#All],4,0),"") -> 24950 | E27: =IFERROR(VLOOKUP($B27,Подбор[#All],5,0),"") -> 19960 | F27: =IFERROR(VLOOKUP($B27,Подбор[#All],19,0),"")
A28: https://ipmatika.kz/products/wifi-smb/wi-tek-wi-ap215/ | B28: WI-AP215 | C28: WI-AP215 AC750 Двухдиапазонная точка доступа c поддержкой PoE, Wi-Fi 5 (802.11AC) | D28: =IFERROR(VLOOKUP($B28,Подбор[#All],4,0),"") -> 49740 | E28: =IFERROR(VLOOKUP($B28,Подбор[#All],5,0),"") -> 39795.25 | F28: =IFERROR(VLOOKUP($B28,Подбор[#All],19,0),"") -> EOL
A29: https://ipmatika.kz/products/wifi-smb/wi-tek-wi-ap216v2/ | B29: WI-AP216 v2 | C29: WI-AP216 точка доступа Wi-Fi 5 AC1200 серии Lite для установки в помещении | D29: =IFERROR(VLOOKUP($B29,Подбор[#All],4,0),"") -> 25200 | E29: =IFERROR(VLOOKUP($B29,Подбор[#All],5,0),"") -> 20160.8 | F29: =IFERROR(VLOOKUP($B29,Подбор[#All],19,0),"")
A30: https://ipmatika.kz/products/wifi-smb/wi-tek-wi-ap217/ | B30: WI-AP217 | C30: WI-AP217 AC1200 Гигабитная двухдиапазонная точка доступа c поддержкой PoE, Wi-Fi 5 (802.11AC Wave2) | D30: =IFERROR(VLOOKUP($B30,Подбор[#All],4,0),"") -> 69640 | E30: =IFERROR(VLOOKUP($B30,Подбор[#All],5,0),"") -> 55713.35 | F30: =IFERROR(VLOOKUP($B30,Подбор[#All],19,0),"")
A31: https://ipmatika.kz/products/wifi-smb/wi-tek-wi-ap217-lite/ | B31: WI-AP217-Lite | C31: WI-AP217-Lite Гигабитная двухдиапазонная точка доступа c поддержкой PoE, Wi-Fi 5 (802.11AC Wave2) | D31: =IFERROR(VLOOKUP($B31,Подбор[#All],4,0),"") -> 50410 | E31: =IFERROR(VLOOKUP($B31,Подбор[#All],5,0),"") -> 40329.575 | F31: =IFERROR(VLOOKUP($B31,Подбор[#All],19,0),"") -> EOL
A32: https://ipmatika.kz/products/wifi-smb/wi-tek-wi-ap217-lite-v2/ | B32: WI-AP217-Lite v2 | C32: WI-AP217-Lite точка доступа потолочная Wi-Fi 5 (802.11AC), PoE, до 100 клиентов | D32: =IFERROR(VLOOKUP($B32,Подбор[#All],4,0),"") -> 43780 | E32: =IFERROR(VLOOKUP($B32,Подбор[#All],5,0),"") -> 35026.2 | F32: =IFERROR(VLOOKUP($B32,Подбор[#All],19,0),"") -> NEW
... A43: https://ipmatika.kz/products/wifi-smb/wi-tek-wi-ap417P/ | B43: WI-AP417P | C43: WI-AP417P точка доступа Wi-Fi 5 (802.11aс) серии Project для встраивания в стену, PoE, 4GE | D43: =IFERROR(VLOOKUP($B43,Подбор[#All],4,0),"") -> 46430 | E43: =IFERROR(VLOOKUP($B43,Подбор[#All],5,0),"") -> 37147.55 | F43: =IFERROR(VLOOKUP($B43,Подбор[#All],19,0),"") -> EOL
A44: https://ipmatika.kz/products/wifi-smb/wi-tek-wi-ap510/ | B44: WI-AP510 | C44: WI-AP510 AC1200 Внешняя двухдиапазонная точка доступа c поддержкой PoE, Wi-Fi 5 (802.11AC Wave2) | D44: 187140 | E44: 140250 | F44: Акция
A45: https://ipmatika.kz/products/wifi-smb/wi-tek-wi-ap518ax/ | B45: WI-AP518AX | C45: WI-AP518AX Внешняя двухдиапазонная точка доступа c поддержкой PoE, Wi-Fi 6 (802.11AX) | D45: =IFERROR(VLOOKUP($B45,Подбор[#All],4,0),"") -> 514270 | E45: =IFERROR(VLOOKUP($B45,Подбор[#All],5,0),"") -> 411414.3 | F45: =IFERROR(VLOOKUP($B45,Подбор[#All],19,0),"") -> EOL
A46: https://ipmatika.kz/products/wifi-smb/wi-tek-wi-ap520ax-d/ | B46: WI-AP520AX-D | C46: WI-AP520AX-D, внешняя двухдиапазонная точка доступа c поддержкой PoE, Wi-Fi6, SFP | D46: =IFERROR(VLOOKUP($B46,Подбор[#All],4,0),"") -> 212250 | E46: =IFERROR(VLOOKUP($B46,Подбор[#All],5,0),"") -> 169803.7 | F46: =IFERROR(VLOOKUP($B46,Подбор[#All],19,0),"")
A47: https://ipmatika.kz/products/opticheskie-moduli/ | B47: SFP модули | D47: =IFERROR(VLOOKUP($B47,Подбор[#All],4,0),"") | E47: =IFERROR(VLOOKUP($B47,Подбор[#All],5,0),"") | F47: =IFERROR(VLOOKUP($B47,Подбор[#All],19,0),"")
A48: https://ipmatika.kz/products/opticheskie-moduli/wi-sfp10lc-20km/ | B48: WI-SFP10LC-20KM | C48: WI-SFP10LC-20KM, Модуль SFP WDM, дальность до 20км (14dB), комплект 2шт 1310/1550нм | D48: =IFERROR(VLOOKUP($B48,Подбор[#All],4,0),"") -> 13270 | E48: =IFERROR(VLOOKUP($B48,Подбор[#All],5,0),"") -> 10614.725 | F48: =IFERROR(VLOOKUP($B48,Подбор[#All],19,0),"")
A49: https://ipmatika.kz/products/opticheskie-moduli/wi-sfp10lc-3km/ | B49: WI-SFP10LC-3KM | C49: WI-SFP10LC-3KM, Модуль SFP WDM, дальность до 3км (6dB), комплект 2шт 1310/1550нм | D49: =IFERROR(VLOOKUP($B49,Подбор[#All],4,0),"") -> 10620 | E49: =IFERROR(VLOOKUP($B49,Подбор[#All],5,0),"") -> 8493.375 | F49: =IFERROR(VLOOKUP($B49,Подбор[#All],19,0),"")
A50: https://ipmatika.kz/products/opticheskie-moduli/wi-sfp10sc-20km/ | B50: WI-SFP10SC-20KM | C50: WI-SFP10SC-20KM, Модуль SFP WDM, дальность до 20км (14dB), комплект 2шт 1310/1550нм | D50: =IFERROR(VLOOKUP($B50,Подбор[#All],4,0),"") -> 13270 | E50: =IFERROR(VLOOKUP($B50,Подбор[#All],5,0),"") -> 10614.725 | F50: =IFERROR(VLOOKUP($B50,Подбор[#All],19,0),"")
...

Sheet Fanvil
A1: URL | B1: Артикул | C1: Описание | D1: KZ РРЦ | E1: Цена Сайт | F1: Status
A2: https://ipmatika.kz/products/2-wire-shlyuzy/ | B2: 2-Wire коммутаторы | F2: =IFERROR(VLOOKUP($B2,Подбор[#All],19,0),"")
A3: https://ipmatika.kz/products/2-wire-shlyuzy/fanvil-pn1/ | B3: PN1 | C3: PN1, SIP-шлюз для подключения IP-телефонов по двухжильному проводу | D3: =IFERROR(VLOOKUP($B3,Подбор[#All],4,0),"") -> 94310 | E3: =D3*0.93 -> 87708.3 | F3: =IFERROR(VLOOKUP($B3,Подбор[#All],19,0),"")
A4: https://ipmatika.kz/products/2-wire-shlyuzy/fanvil-pn24/ | B4: PN24 | C4: PN24, SIP-шлюз для подключения IP-телефонов по двухжильному проводу | D4: =IFERROR(VLOOKUP($B4,Подбор[#All],4,0),"") -> 183960 | E4: =D4*0.93 -> 171082.8 | F4: =IFERROR(VLOOKUP($B4,Подбор[#All],19,0),"")
A5: https://ipmatika.kz/products/2-wire-shlyuzy/fanvil-pn8/ | B5: PN8 | C5: PN8, SIP-шлюз для подключения IP-телефонов по двухжильному проводу | D5: =IFERROR(VLOOKUP($B5,Подбор[#All],4,0),"") -> 98110 | E5: =D5*0.93 -> 91242.3 | F5: =IFERROR(VLOOKUP($B5,Подбор[#All],19,0),"")
A6: https://ipmatika.kz/products/roip-shlyuzy/ | B6: RoIP-шлюзы | E6: =D6*0.93 -> 0 | F6: =IFERROR(VLOOKUP($B6,Подбор[#All],19,0),"")
A7: https://ipmatika.kz/products/roip-shlyuzy/W712/ | B7: LW712 | C7: RoIP-шлюз Linkvil W712 | D7: =IFERROR(VLOOKUP($B7,Подбор[#All],4,0),"") -> 319940 | E7: =D7*0.93 -> 297544.2 | F7: =IFERROR(VLOOKUP($B7,Подбор[#All],19,0),"")
A8: https://ipmatika.kz/products/voip-fxs-fxo/ | B8: VoIP-шлюзы FXS/FXO | E8: =D8*0.93 -> 0 | F8: =IFERROR(VLOOKUP($B8,Подбор[#All],19,0),"")
A9: https://ipmatika.kz/products/voip-fxs-fxo/GA10/ | B9: GA10 | C9: VoIP-шлюз Fanvil GA10, 1*FXS | E9: =D9*0.93 -> 0 | F9: =IFERROR(VLOOKUP($B9,Подбор[#All],19,0),"")
A10: https://ipmatika.kz/products/sip-opoveshchenie/ | B10: SIP-колонки Fanvil | E10: =D10*0.93 -> 0 | F10: =IFERROR(VLOOKUP($B10,Подбор[#All],19,0),"")
A11: https://ipmatika.kz/products/sip-opoveshchenie/Fanvil-A201/ | B11: A201 | C11: Fanvil A201, SIP-громкоговоритель, PoE, встраиваемый | D11: =IFERROR(VLOOKUP($B11,Подбор[#All],4,0),"") -> 88240 | E11: =D11*0.93 -> 82063.2 | F11: =IFERROR(VLOOKUP($B11,Подбор[#All],19,0),"")
A12: https://ipmatika.kz/products/sip-opoveshchenie/Fanvil-A212/ | B12: A212W | C12: Fanvil A212, SIP-громкоговоритель, PoE, настенный, белый | D12: =IFERROR(VLOOKUP($B12,Подбор[#All],4,0),"") -> 110310 | E12: =D12*0.93 -> 102588.3 | F12: =IFERROR(VLOOKUP($B12,Подбор[#All],19,0),"")
A13: https://ipmatika.kz/products/sip-opoveshchenie/Fanvil-A212/ | B13: A212B | C13: Fanvil A212, SIP-громкоговоритель, PoE, настенный, черный | D13: =IFERROR(VLOOKUP($B13,Подбор[#All],4,0),"") -> 110310 | E13: =D13*0.93 -> 102588.3 | F13: =IFERROR(VLOOKUP($B13,Подбор[#All],19,0),"")
A14: https://ipmatika.kz/products/sip-opoveshchenie/Fanvil-A233/ | B14: A233 | C14: Fanvil A233, SIP-громкоговоритель, PoE, рупорный, уличный | D14: =IFERROR(VLOOKUP($B14,Подбор[#All],4,0),"") -> 155730 | E14: =D14*0.93 -> 144828.9 | F14: =IFERROR(VLOOKUP($B14,Подбор[#All],19,0),"")
A15: https://ipmatika.kz/products/sip-opoveshchenie/Fanvil-FH-S01/ | B15: FH-S01 | C15: Fanvil FH-S01, SIP-громкоговоритель, PoE, встраиваемый | D15: =IFERROR(VLOOKUP($B15,Подбор[#All],4,0),"") -> 142750 | E15: =D15*0.93 -> 132757.5 | F15: =IFERROR(VLOOKUP($B15,Подбор[#All],19,0),"")
A16: https://ipmatika.kz/products/wifi-telefony/ | B16: Wi-Fi-телефоны | F16: =IFERROR(VLOOKUP($B16,Подбор[#All],19,0),"")
A17: https://ipmatika.kz/products/wifi-telefony/Linkvil-W610W/ | B17: FLW610W | C17: (Linkvil) W610W, цветной экран, б/п, Wi-Fi 2,4G/5G | D17: =IFERROR(VLOOKUP($B17,Подбор[#All],4,0),"") -> 61660 | E17: =D17*0.93 -> 57343.8 | F17: =IFERROR(VLOOKUP($B17,Подбор[#All],19,0),"")
A18: https://ipmatika.kz/products/wifi-telefony/Linkvil-W611W/ | B18: FLW611W | C18: (Linkvil) W611W, цветной экран, IP67, б/п, Wi-Fi 2,4G/5G | D18: =IFERROR(VLOOKUP($B18,Подбор[#All],4,0),"") -> 120510 | E18: =D18*0.93 -> 112074.3 | F18: =IFERROR(VLOOKUP($B18,Подбор[#All],19,0),"")
A19: https://ipmatika.kz/products/konsoli-monitoringa-i-opoveshcheniya/ | B19: Консоли мониторинга и управления | F19: =IFERROR(VLOOKUP($B19,Подбор[#All],19,0),"")
A20: https://ipmatika.kz/products/konsoli-monitoringa-i-opoveshcheniya/Fanvil-A320/ | B20: A320 | C20: A320, цветной экран, 20 аккаунтов, Android, камера | D20: =IFERROR(VLOOKUP($B20,Подбор[#All],4,0),"") -> 324440 | E20: =D20*0.93 -> 301729.2 | F20: =IFERROR(VLOOKUP($B20,Подбор[#All],19,0),"")
A21: https://ipmatika.kz/products/konsoli-monitoringa-i-opoveshcheniya/Fanvil-A320/ | B21: A320white | C21: A320, цветной экран, 20 аккаунтов, Android, камера, белый | D21: =IFERROR(VLOOKUP($B21,Подбор[#All],4,0),"") -> 324440 | E21: =D21*0.93 -> 301729.2 | F21: =IFERROR(VLOOKUP($B21,Подбор[#All],19,0),"")
A22: https://ipmatika.kz/products/konsoli-monitoringa-i-opoveshcheniya/Fanvil-A320i/ | B22: A320i | C22: A320i, цветной экран, 20 аккаунтов, Android, камера | D22: =IFERROR(VLOOKUP($B22,Подбор[#All],4,0),"") -> 480170 | E22: =D22*0.93 -> 446558.1 | F22: =IFERROR(VLOOKUP($B22,Подбор[#All],19,0),"")
A23: https://ipmatika.kz/products/konsoli-monitoringa-i-opoveshcheniya/Fanvil-A320i/ | B23: A320iwhite | C23: A320i, цветной экран, 20 аккаунтов, Android, камера, белый | D23: =IFERROR(VLOOKUP($B23,Подбор[#All],4,0),"") -> 480170 | E23: =D23*0.93 -> 446558.1 | F23: =IFERROR(VLOOKUP($B23,Подбор[#All],19,0),"")
A24: https://ipmatika.kz/products/konsoli-monitoringa-i-opoveshcheniya/Fanvil-X210i/ | B24: X210iO | C24: Fanvil X210i, цветной экран, 20 аккаунтов | D24: =IFERROR(VLOOKUP($B24,Подбор[#All],4,0),"") | F24: =IFERROR(VLOOKUP($B24,Подбор[#All],19,0),"")
A25: https://ipmatika.kz/products/konsoli-monitoringa-i-opoveshcheniya/Fanvil-X210i/ | B25: X210 | C25: X210, цветной экран, 20 аккаунтов | D25: =IFERROR(VLOOKUP($B25,Подбор[#All],4,0),"") -> 106240 | E25: =D25*0.93 -> 98803.2 | F25: =IFERROR(VLOOKUP($B25,Подбор[#All],19,0),"")
A26: https://ipmatika.kz/products/konsoli-monitoringa-i-opoveshcheniya/Fanvil-X210i/ | B26: X210i | C26: X210i, цветной экран, 20 аккаунтов | D26: =IFERROR(VLOOKUP($B26,Подбор[#All],4,0),"") -> 285510 | E26: =D26*0.93 -> 265524.3 | F26: =IFERROR(VLOOKUP($B26,Подбор[#All],19,0),"")
A27: https://ipmatika.kz/products/konsoli-monitoringa-i-opoveshcheniya/X5UR/ | B27: X5U | C27: X5U, красный, 16 аккаунтов, 2 цветных ЖК-экрана, PoE | D27: =IFERROR(VLOOKUP($B27,Подбор[#All],4,0),"") | F27: =IFERROR(VLOOKUP($B27,Подбор[#All],19,0),"")
A28: https://ipmatika.kz/products/hotel-phone/ | B28: Отельные телефоны | F28: =IFERROR(VLOOKUP($B28,Подбор[#All],19,0),"")
A29: https://ipmatika.kz/products/hotel-phone/Fanvil-H1-2023/ | B29: FH1PBPSU | C29: H1 отельный, 2 аккаунта, без экрана, PoE, б/п | D29: =IFERROR(VLOOKUP($B29,Подбор[#All],4,0),"") -> 29120 | E29: =D29*0.93 -> 27081.6 | F29: =IFERROR(VLOOKUP($B29,Подбор[#All],19,0),"")
A30: https://ipmatika.kz/products/hotel-phone/fanvil-h1-2-wire/ | B30: FH12WIRE | C30: H1-2 Wire отельный, 2 аккаунта, без экрана, б/п | D30: =IFERROR(VLOOKUP($B30,Подбор[#All],4,0),"") -> 29120 | E30: =D30*0.93 -> 27081.6 | F30: =IFERROR(VLOOKUP($B30,Подбор[#All],19,0),"")
A31: https://ipmatika.kz/products/hotel-phone/H2UW/ | B31: FH2UPW | C31: H2U отельный, белый, 2 аккаунта, PoE, без б/п | D31: =IFERROR(VLOOKUP($B31,Подбор[#All],4,0),"") -> 23830 | E31: =D31*0.93 -> 22161.9 | F31: =IFERROR(VLOOKUP($B31,Подбор[#All],19,0),"")
A32: https://ipmatika.kz/products/vnutrennie-sip-paneli/H2URI/ | B32: FH2UPR | C32: H2U отельный, красный, 2 аккаунта, PoE, без б/п | D32: =IFERROR(VLOOKUP($B32,Подбор[#All],4,0),"") -> 34410 | E32: =D32*0.93 -> 32001.3 | F32: =IFERROR(VLOOKUP($B32,Подбор[#All],19,0),"")
A33: https://ipmatika.kz/products/hotel-phone/H2UB/ | B33: FH2UPB | C33: H2U отельный, чёрный, 2 аккаунта, PoE, без б/п | D33: =IFERROR(VLOOKUP($B33,Подбор[#All],4,0),"") -> 23830 | E33: =D33*0.93 -> 22161.9 | F33: =IFERROR(VLOOKUP($B33,Подбор[#All],19,0),"")
A34: https://ipmatika.kz/products/hotel-phone/Fanvil-H3/ | B34: FH3PB sale | C34: H3 отельный, 2 аккаунта, без экрана, PoE, б/п | D34: 31710 | E34: =D34*0.93 -> 29490.3 | F34: Акция
A35: https://ipmatika.kz/products/hotel-phone/Fanvil-H3/ | B35: FH3PPSUB | C35: H3 отельный, 2 аккаунта, без экрана, PoE, б/п | D35: =IFERROR(VLOOKUP($B35,Подбор[#All],4,0),"") -> 25330 | E35: =D35*0.93 -> 23556.9 | F35: =IFERROR(VLOOKUP($B35,Подбор[#All],19,0),"") -> EOL
A36: https://ipmatika.kz/products/hotel-phone/Fanvil-H3W/ | B36: FH3PPSUW | C36: H3 отельный, белый, 2 аккаунта, без экрана, PoE, б/п | D36: =IFERROR(VLOOKUP($B36,Подбор[#All],4,0),"") -> 35960 | E36: =D36*0.93 -> 33442.8 | F36: =IFERROR(VLOOKUP($B36,Подбор[#All],19,0),"") -> EOL
A37: https://ipmatika.kz/products/hotel-phone/Fanvil-H3WF/ | B37: FH3WPPSUB | C37: H3W отельный, 2 аккаунта, без экрана, PoE, б/п, WiFi | D37: =IFERROR(VLOOKUP($B37,Подбор[#All],4,0),"") -> 33500 | E37: =D37*0.93 -> 31155 | F37: =IFERROR(VLOOKUP($B37,Подбор[#All],19,0),"") -> EOL
A38: https://ipmatika.kz/products/hotel-phone/Fanvil-H3WFW/ | B38: FH3WPPSUW | C38: H3W отельный, белый, 2 аккаунта, без экрана, PoE, б/п, WiFi | D38: =IFERROR(VLOOKUP($B38,Подбор[#All],4,0),"") -> 40850 | E38: =D38*0.93 -> 37990.5 | F38: =IFERROR(VLOOKUP($B38,Подбор[#All],19,0),"") -> EOL
A39: https://ipmatika.kz/products/hotel-phone/Fanvil-H4/ | B39: FH4PPSUB | C39: H4 отельный, 2 аккаунта, без экрана, PoE, б/п | D39: =IFERROR(VLOOKUP($B39,Подбор[#All],4,0),"") -> 33100 | E39: =D39*0.93 -> 30783 | F39: =IFERROR(VLOOKUP($B39,Подбор[#All],19,0),"")
A40: https://ipmatika.kz/products/hotel-phone/Fanvil-H4-white/ | B40: FH4PPSUW | C40: H4 отельный, белый, 2 аккаунта, без экрана, PoE, б/п | D40: =IFERROR(VLOOKUP($B40,Подбор[#All],4,0),"") -> 33100 | E40: =D40*0.93 -> 30783 | F40: =IFERROR(VLOOKUP($B40,Подбор[#All],19,0),"")
...

Sheet VT
A1: URL | B1: Артикул | C1: Описание | D1: KZ РРЦ | E1: Цена Сайт | F1: Status
A2: https://ipmatika.kz/products/garnitury-vt/ | B2: Гарнитуры VT | F2: =IFERROR(VLOOKUP($B2,Подбор[#All],19,0),"")
A3: https://ipmatika.kz/products/besprovodnye/ | B3: Беспроводные гарнитуры
A4: https://ipmatika.kz/products/bluetooth/ | B4: Беспроводные гарнитуры Bluetooth
A5: https://ipmatika.kz/products/bluetooth/vt_flow/ | B5: VT FLOW | C5: VT FLOW, Дуо, Hi-Fi звук, 30м Bluetooth, индикатор занятости, ANC, складная, чехол, Dongle | D5: 133100 | E5: =D5*0.93 -> 123783
A6: https://ipmatika.kz/products/bluetooth/VT9200-D/ | B6: VT9200-D | C6: VT9200-D, Дуо, HD звук, 30м Bluetooth, USB Type-C Dongle | D6: 52800 | E6: =D6*0.93 -> 49104
A7: https://ipmatika.kz/products/bluetooth/VT9200/ | B7: VT9200 | C7: VT9200, Моно, HD звук, 30м Bluetooth, USB Type-C Dongle | D7: 46750 | E7: =D7*0.93 -> 43477.5
A8: https://ipmatika.kz/products/bluetooth/VT9200_Without/ | B8: VT9200_Without | C8: VT9200, Моно, HD звук, 30м Bluetooth, USB Type-C без донгла | D8: 35750 | E8: =D8*0.93 -> 33247.5
A9: https://ipmatika.kz/products/bluetooth/VT-VT9500-D/ | B9: VT9500-D | C9: VT9500-D, Дуо, HD звук, 10м Bluetooth | D9: 33300 | E9: =D9*0.93 -> 30969
A10: https://ipmatika.kz/products/bluetooth/VT9605-D/ | B10: VT9605-D | C10: VT9605-D, Дуо, Hi-Fi звук, 30м Bluetooth, индикатор занятости, в комплекте с USB-BT адаптером | D10: 53020 | E10: =D10*0.93 -> 49308.6
A11: https://ipmatika.kz/products/bluetooth/VT-X300BT-D/ | B11: X300BT-D | C11: X300BT-D, Дуо, Hi-Fi звук, 30м Bluetooth, индикатор занятости, в комплекте с USB-BT адаптером | D11: 114400 | E11: =D11*0.93 -> 106392
A12: https://ipmatika.kz/products/dect-/ | B12: Беспроводные гарнитуры DECT
A13: https://ipmatika.kz/products/dect-/W310U-D/ | B13: W310U-D | C13: VT W310U-D, Дуо, HD звук, 150м DECT, USB-dogle type-C, чехол | D13: 129250 | E13: =D13*0.93 -> 120202.5
A14: https://ipmatika.kz/products/dect-/W310U/ | B14: W310U | C14: VT W310U, Моно, HD звук, 150м DECT, USB-dogle type-C, чехол | D14: 119900 | E14: =D14*0.93 -> 111507
A15: https://ipmatika.kz/products/dect-/VT-VT9000_LFT/ | B15: VT9000_LFT | C15: VT9000 в комплекте с микролифтом, Моно, HD звук, 150м DECT, для телефона | D15: 124140 | E15: =D15*0.93 -> 115450.2
A16: https://ipmatika.kz/products/dect-/VT-VT9000-D_LFT/ | B16: VT9000-D_LFT | C16: VT9000-D в комплекте с микролифтом, Дуо, HD звук, 150м DECT, для телефона | D16: 130290 | E16: =D16*0.93 -> 121169.7
A17: https://ipmatika.kz/products/dect-/VT-VT9000-D/ | B17: VT9000-D | C17: VT9000-D, Дуо, HD звук, 150м DECT, для телефона | D17: 112000 | E17: =D17*0.93 -> 104160
A18: https://ipmatika.kz/products/dect-/VT-VT9000/ | B18: VT9000 | C18: VT9000, Моно, HD звук, 150м DECT, для телефона | D18: 58740 | E18: =D18*0.93 -> 54628.2
A19: https://ipmatika.kz/products/dect-/VT-VT9400-D/ | B19: VT9400-D | C19: VT9400-D, Дуо, HD звук, 150м DECT, для компьютера и телефона | D19: 118000 | E19: =D19*0.93 -> 109740
A20: https://ipmatika.kz/products/dect-/VT-VT9400/ | B20: VT9400 | C20: VT9400, Моно, HD звук, 150м DECT, для компьютера и телефона | D20: 67060 | E20: =D20*0.93 -> 62365.8
A21: https://ipmatika.kz/products/usb-videokamery-i-byod-resheniya/ | B21: Веб-камеры
A22: https://ipmatika.kz/products/usb-videokamery-i-byod-resheniya/vt-webcam-v100/ | B22: V100 | C22: VT V100 USB веб-камера Full HD | D22: 38500 | E22: =D22*0.93 -> 35805
A23: https://ipmatika.kz/products/garnitury-zashchishchyennye/ | B23: Гарнитуры защищённые для склада
A24: https://ipmatika.kz/products/garnitury-zashchishchyennye/vt-w300/ | B24: W300 | C24: W300 защищенная, моно, 30м Bluetooth, от -20 до +50 град, 2 аккумулятора | D24: 207460 | E24: =D24*0.93 -> 192937.8
A25: https://ipmatika.kz/products/provodnye/ | B25: Проводные гарнитуры
A26: https://ipmatika.kz/products/provodnye/VT-VT1000-RJ9%2803%29/ | B26: VT1000 RJ9(03) | C26: VT1000 RJ9(03), Моно, Узкополосный звук, SE, усовершенствованный микрофон | D26: 10000 | E26: =D26*0.93 -> 9300
A27: https://ipmatika.kz/products/archive/provodnye/VT-VT1000-USB/ | B27: VT1000 USB old | C27: VT1000 USB, Моно, Узкополосный звук, SE, усовершенствованный | D27: 11440 | E27: =D27*0.93 -> 10639.2
A28: https://ipmatika.kz/products/provodnye/VT-VT1000-D-RJ9%2803%29/ | B28: VT1000-D RJ9(03) | C28: VT1000-D RJ9(03), Дуо, Узкополосный звук SE, усовершенствованный микрофон | D28: 11610 | E28: =D28*0.93 -> 10797.3
A29: https://ipmatika.kz/products/provodnye/VT-VT1000-D-USB/ | B29: VT1000-D USB | C29: VT1000-D USB, Дуо, Узкополосный звук SE, усовершенствованный микрофон | D29: 19950 | E29: =D29*0.93 -> 18553.5
A30: https://ipmatika.kz/products/provodnye/VT-VT5000-QD%28P%29-RJ9%2803%29/ | B30: VT5000 QD(P)-RJ9(03) | C30: VT5000 QD(P)-RJ9(03), Моно, Узкополосный звук, QD, переходник QD-RJ09(03) | D30: 15770 | E30: =D30*0.93 -> 14666.1
A31: https://ipmatika.kz/products/provodnye/VT5000_USB/ | B31: VT5000 USB | C31: VT5000 USB, Моно, HD звук | D31: 17890 | E31: =D31*0.93 -> 16637.7
A32: https://ipmatika.kz/products/provodnye/VT-VT5000-D-QD%28P%29-RJ9%2803%29/ | B32: VT5000-D QD(P)-RJ9(03) | C32: VT5000-D QD(P)-RJ9(03), Дуо, Узкополосный звук, QD, переходник QD-RJ09(03) | D32: 19500 | E32: =D32*0.93 -> 18135
A33: https://ipmatika.kz/products/provodnye/VT5000-D_USB/ | B33: VT5000-D USB | C33: VT5000-D USB, Дуо, HD звук | D33: 19930 | E33: =D33*0.93 -> 18534.9
A34: https://ipmatika.kz/products/provodnye/VT-VT6200-QD%28P%29-RJ9%2803%29/ | B34: VT6200 QD(P)-RJ9(03) | C34: VT6200 QD(P)-RJ9(03), Моно, HD звук, QD, переходник QD-RJ09(03) | D34: 19570 | E34: =D34*0.93 -> 18200.1
A35: https://ipmatika.kz/products/provodnye/VT-VT6200-USB/ | B35: VT6200 USB | C35: VT6200 USB, Моно, HD звук | D35: 22370 | E35: =D35*0.93 -> 20804.1
A36: https://ipmatika.kz/products/provodnye/VT-VT6200-D-QD%28P%29-RJ9%2803%29/ | B36: VT6200-D QD(P)-RJ9(03) | C36: VT6200-D QD(P)-RJ9(03), Дуо, HD звук, QD, переходник QD-RJ09(03) | D36: 22370 | E36: =D36*0.93 -> 20804.1
A37: https://ipmatika.kz/products/provodnye/VT-VT6200-D-USB/ | B37: VT6200-D USB | C37: VT6200-D USB, Дуо, HD звук | D37: 24440 | E37: =D37*0.93 -> 22729.2
... A43: https://ipmatika.kz/products/provodnye/X208/ | B43: X208 | C43: X208, Моно, HD звук, разъемы 3,5 мм Jack и USB | D43: 36300 | E43: =D43*0.93 -> 33759
A44: https://ipmatika.kz/products/spikerfony/ | B44: Спикерфоны VT
A45: https://ipmatika.kz/products/spikerfony/VT-CS61/ | B45: CS61ENC-A | C45: CS61ENC-A USB/Bluetooth в комплекте с BT-dongle, переходником USB-TypeA-USB-TypeC | D45: 92000 | E45: =D45*0.93 -> 85560
...

Sheet Qbic
A1: URL | B1: Артикул | C1: Описание | D1: KZ РРЦ | E1: KZ Дилер | F1: Status
A2: https://ipmatika.kz/products/promyshlennye-i-kommercheskie-kompyutery/ | B2: Панельные компьютеры и мини-ПК | F2: =IFERROR(VLOOKUP($B2,Подбор[#All],19,0),"")
A3: https://ipmatika.kz/products/panelnye-kompyutery/ | B3: Панельные ПК | E3: =IFERROR(D3*0.85,"") | F3: =IFERROR(VLOOKUP($B3,Подбор[#All],19,0),"")
A4: https://ipmatika.kz/products/panelnye-kompyutery/ep-0400/ | B4: EP-0400 | C4: EP-0400 - Дисплей e-ink 4.2'', 400x300, 3 цвета: черн, белый, красный, 3 кнопки | D4: =IFERROR(VLOOKUP($B4,Подбор[#All],4,0),"") -> 90750 | E4: =IFERROR(VLOOKUP($B4,Подбор[#All],5,0),"") -> 77137.5 | F4: =IFERROR(VLOOKUP($B4,Подбор[#All],19,0),"") -> Под заказ
A5: https://ipmatika.kz/products/panelnye-kompyutery/ep-0700/ | B5: EP-0700 | C5: EP-0700 - Дисплей e-ink 7.5'', 800x480, 3 цвета: черн, белый, красный, 3 кнопки | D5: =IFERROR(VLOOKUP($B5,Подбор[#All],4,0),"") -> 181500 | E5: =IFERROR(VLOOKUP($B5,Подбор[#All],5,0),"") -> 154275 | F5: =IFERROR(VLOOKUP($B5,Подбор[#All],19,0),"") -> Под заказ
A6: https://ipmatika.kz/products/panelnye-kompyutery/qbic-td-0350-bh/ | B6: TD-0350-BH125 | C6: TD-0350, 3,5" сенсорная панель, BT, NFC/RFID/HID, RCC, черный | D6: =IFERROR(VLOOKUP($B6,Подбор[#All],4,0),"") -> 334400 | E6: =IFERROR(VLOOKUP($B6,Подбор[#All],5,0),"") -> 284240 | F6: =IFERROR(VLOOKUP($B6,Подбор[#All],19,0),"") -> EOL
A7: https://ipmatika.kz/products/panelnye-kompyutery/TD-0360/ | B7: TD-0360-S | C7: TD-0360, 3,6" сенсорная панель, BT, NFC/RFID, RCC, серебристый | D7: =IFERROR(VLOOKUP($B7,Подбор[#All],4,0),"") -> 308000 | E7: =IFERROR(VLOOKUP($B7,Подбор[#All],5,0),"") -> 261800 | F7: =IFERROR(VLOOKUP($B7,Подбор[#All],19,0),"") -> NEW
A8: https://ipmatika.kz/products/panelnye-kompyutery/qbic-td-1050pro-b-/ | B8: TD-1050PRO-B | C8: TD-1050 PRO, 10" сенсорная панель, BT, NFC/RFID, RCC, черный | D8: =IFERROR(VLOOKUP($B8,Подбор[#All],4,0),"") -> 726000 | E8: =IFERROR(VLOOKUP($B8,Подбор[#All],5,0),"") -> 617100 | F8: =IFERROR(VLOOKUP($B8,Подбор[#All],19,0),"") -> EOL
A9: https://ipmatika.kz/products/panelnye-kompyutery/qbic-td-1060-slim/ | B9: TD-1060 Slim | C9: TD-1060 Slim, 10" сенсорная панель, BT, RCC, черный | D9: =IFERROR(VLOOKUP($B9,Подбор[#All],4,0),"") -> 533500 | E9: =IFERROR(VLOOKUP($B9,Подбор[#All],5,0),"") -> 453475 | F9: =IFERROR(VLOOKUP($B9,Подбор[#All],19,0),"")
A10: https://ipmatika.kz/products/panelnye-kompyutery/qbic-td-1070/ | B10: TD-1070-BH | C10: TD-1070, 10" сенсорная панель Full HD, BT, NFC/HID/RFID, RCC, Android11 | D10: =IFERROR(VLOOKUP($B10,Подбор[#All],4,0),"") -> 1034000 | E10: =IFERROR(VLOOKUP($B10,Подбор[#All],5,0),"") -> 878900 | F10: =IFERROR(VLOOKUP($B10,Подбор[#All],19,0),"") -> Под заказ
A11: https://ipmatika.kz/products/panelnye-kompyutery/qbic-td-1070/ | B11: TD-1070-B | C11: TD-1070, 10" сенсорная панель Full HD, BT, NFC/RFID, RCC, Android11 | D11: =IFERROR(VLOOKUP($B11,Подбор[#All],4,0),"") -> 825000 | E11: =IFERROR(VLOOKUP($B11,Подбор[#All],5,0),"") -> 701250 | F11: =IFERROR(VLOOKUP($B11,Подбор[#All],19,0),"") -> ОБРАЗЕЦ
A12: https://ipmatika.kz/products/panelnye-kompyutery/qbic-td-1070-lite/ | B12: TD-1070 Lite | C12: TD-1070L-S, 10" сенсорная панель Full HD, BT, NFC/RFID, RCC, Android12 | D12: =IFERROR(VLOOKUP($B12,Подбор[#All],4,0),"") -> 764500 | E12: =IFERROR(VLOOKUP($B12,Подбор[#All],5,0),"") -> 649825 | F12: =IFERROR(VLOOKUP($B12,Подбор[#All],19,0),"")
A13: https://ipmatika.kz/products/panelnye-kompyutery/qbic-td-1070-lite/ | B13: TD-1070 Lite H | C13: TD-1070L-SH, 10" сенсорная панель Full HD, BT, NFC/RFID/HID, RCC, Android12 | D13: =IFERROR(VLOOKUP($B13,Подбор[#All],4,0),"") -> 946000 | E13: =IFERROR(VLOOKUP($B13,Подбор[#All],5,0),"") -> 804100 | F13: =IFERROR(VLOOKUP($B13,Подбор[#All],19,0),"") -> Под заказ
A14: https://ipmatika.kz/products/box-pc/ | B14: Промышленные мини-ПК | D14: =IFERROR(VLOOKUP($B14,Подбор[#All],4,0),"") | E14: =IFERROR(VLOOKUP($B14,Подбор[#All],5,0),"") | F14: =IFERROR(VLOOKUP($B14,Подбор[#All],19,0),"")
A15: https://ipmatika.kz/products/box-pc/BXP-100/ | B15: BXP-100 | C15: BXP-100 - Мини-ПК, HDMI output, 2GB RAM, 32GB storage, micro-SDHC expansion | D15: =IFERROR(VLOOKUP($B15,Подбор[#All],4,0),"") -> 236500 | E15: =IFERROR(VLOOKUP($B15,Подбор[#All],5,0),"") -> 201025 | F15: =IFERROR(VLOOKUP($B15,Подбор[#All],19,0),"")
A16: https://ipmatika.kz/products/box-pc/BXP-320/ | B16: BXP-320 | C16: BXP-320 - Мини-ПК, HDMI output 4K, 4GB RAM, 32GB storage, micro-SDHC expansion | D16: =IFERROR(VLOOKUP($B16,Подбор[#All],4,0),"") -> 588500 | E16: =IFERROR(VLOOKUP($B16,Подбор[#All],5,0),"") -> 500225 | F16: =IFERROR(VLOOKUP($B16,Подбор[#All],19,0),"") -> Под заказ
A17: https://ipmatika.kz/products/box-pc/BXP-321/ | B17: BXP-321 | C17: BXP-321 - Мини-ПК, HDMI input и HDMI output 4K, 4GB RAM, 32GB storage, micro-SDHC expansion | D17: =IFERROR(VLOOKUP($B17,Подбор[#All],4,0),"") -> 638000 | E17: =IFERROR(VLOOKUP($B17,Подбор[#All],5,0),"") -> 542300 | F17: =IFERROR(VLOOKUP($B17,Подбор[#All],19,0),"") -> Под заказ
A18: https://ipmatika.kz/products/box-pc/qbic-bxt-312/ | B18: BXT-312 | C18: BXT-312 - Мини-ПК, 2xHDMI-out (8k, 4k), 1xHDMI-in 4k, 8GB RAM, 128GB storage, micro-SDHC | D18: =IFERROR(VLOOKUP($B18,Подбор[#All],4,0),"") | E18: =IFERROR(VLOOKUP($B18,Подбор[#All],5,0),"") | F18: =IFERROR(VLOOKUP($B18,Подбор[#All],19,0),"")
A19: https://ipmatika.kz/products/box-pc/qbic_BXT_512/ | B19: BXT-512 | C19: BXT-512 - Мини-ПК, Core-i3 7100U/8gb/256ssd/VESA/EU Power Code | D19: =IFERROR(VLOOKUP($B19,Подбор[#All],4,0),"") -> 1314500 | E19: =IFERROR(VLOOKUP($B19,Подбор[#All],5,0),"") -> 1117325 | F19: =IFERROR(VLOOKUP($B19,Подбор[#All],19,0),"")
A20: https://ipmatika.kz/products/sistemy-bronirovaniya/ | B20: Системы бронирования | D20: =IFERROR(VLOOKUP($B20,Подбор[#All],4,0),"") | E20: =IFERROR(VLOOKUP($B20,Подбор[#All],5,0),"") | F20: =IFERROR(VLOOKUP($B20,Подбор[#All],19,0),"")
A21: https://ipmatika.kz/products/doortablet-on-premise/ | B21: Door Tablet | D21: =IFERROR(VLOOKUP($B21,Подбор[#All],4,0),"") | E21: =IFERROR(VLOOKUP($B21,Подбор[#All],5,0),"") | F21: =IFERROR(VLOOKUP($B21,Подбор[#All],19,0),"")
A22: https://ipmatika.kz/products/doortablet-on-premise/DT-PREC/ | B22: DT-PREC | C22: Desk Presence Controller - Лицензия для подключения 1 концентратора AC-210.ex к системе Deskware | D22: =IFERROR(VLOOKUP($B22,Подбор[#All],4,0),"") | E22: =IFERROR(VLOOKUP($B22,Подбор[#All],5,0),"") | F22: =IFERROR(VLOOKUP($B22,Подбор[#All],19,0),"") -> Под заказ
A23: https://ipmatika.kz/products/doortablet-on-premise/DT-PRE/ | B23: DT-PRE | C23: DeskWare Presence license - Отображение статуса занятости 1 рабочего стола без бронирования | D23: =IFERROR(VLOOKUP($B23,Подбор[#All],4,0),"") | E23: =IFERROR(VLOOKUP($B23,Подбор[#All],5,0),"") | F23: =IFERROR(VLOOKUP($B23,Подбор[#All],19,0),"") -> Под заказ
A24: https://ipmatika.kz/products/doortablet-on-premise/DT-PRE/ | B24: DT-API | C24: Door Tablet API - Лицензия на предоставление доступа к серверу стронних устройств и приложений | D24: =IFERROR(VLOOKUP($B24,Подбор[#All],4,0),"") | E24: =IFERROR(VLOOKUP($B24,Подбор[#All],5,0),"") | F24: =IFERROR(VLOOKUP($B24,Подбор[#All],19,0),"") -> Под заказ
A25: https://ipmatika.kz/products/doortablet-on-premise/DT-EN/ | B25: DT-EN | C25: Enterprise Server Licence - Лицензия на серверное ПО для 10 и более переговорных | D25: =IFERROR(VLOOKUP($B25,Подбор[#All],4,0),"") | E25: =IFERROR(VLOOKUP($B25,Подбор[#All],5,0),"") | F25: =IFERROR(VLOOKUP($B25,Подбор[#All],19,0),"") -> Под заказ
A26: https://ipmatika.kz/products/doortablet-on-premise/SUPG/ | B26: SUPG | C26: Enterprise Server Upgrade - Лицензия - обновление сервера со Standard Server на Enterprise | D26: =IFERROR(VLOOKUP($B26,Подбор[#All],4,0),"") | E26: =IFERROR(VLOOKUP($B26,Подбор[#All],5,0),"") | F26: =IFERROR(VLOOKUP($B26,Подбор[#All],19,0),"") -> Под заказ
A27: https://ipmatika.kz/products/doortablet-on-premise/DT-DSKO/ | B27: DT-DSKO | C27: Hot Desk OEM - Лицензия для использования Qbic TD-0350 в системе DeskWare | D27: =IFERROR(VLOOKUP($B27,Подбор[#All],4,0),"") | E27: =IFERROR(VLOOKUP($B27,Подбор[#All],5,0),"") | F27: =IFERROR(VLOOKUP($B27,Подбор[#All],19,0),"") -> Под заказ
A28: https://ipmatika.kz/products/doortablet-on-premise/DT-RMO/ | B28: DT-RMO | C28: OEM Room Licence - Лицензия для подключения 1 ПК Qbic TD-1050/TD-1060 для переговорной | D28: =IFERROR(VLOOKUP($B28,Подбор[#All],4,0),"") | E28: =IFERROR(VLOOKUP($B28,Подбор[#All],5,0),"") | F28: =IFERROR(VLOOKUP($B28,Подбор[#All],19,0),"") -> Под заказ
A29: https://ipmatika.kz/products/doortablet-on-premise/DT-SR/ | B29: DT-SR | C29: Standard Server Licence - Лицензия на серверное ПО для 1-9 переговорных | D29: =IFERROR(VLOOKUP($B29,Подбор[#All],4,0),"") | E29: =IFERROR(VLOOKUP($B29,Подбор[#All],5,0),"") | F29: =IFERROR(VLOOKUP($B29,Подбор[#All],19,0),"") -> Под заказ
A30: https://ipmatika.kz/products/doortablet-on-premise/DT-WF/ | B30: DT-WF | C30: Wayfinding Interactivity Licence - Лицензия для ПК с Touch-screen дисплеем | D30: =IFERROR(VLOOKUP($B30,Подбор[#All],4,0),"") | E30: =IFERROR(VLOOKUP($B30,Подбор[#All],5,0),"") | F30: =IFERROR(VLOOKUP($B30,Подбор[#All],19,0),"") -> Под заказ
B31: BXT-512_DT-EN | C31: ПК BXT-512 в комплекте с ПО DoorTablet Enterprise Server Win IoT | D31: =IFERROR(VLOOKUP($B31,Подбор[#All],4,0),"") | E31: =IFERROR(VLOOKUP($B31,Подбор[#All],5,0),"") | F31: =IFERROR(VLOOKUP($B31,Подбор[#All],19,0),"") -> Под заказ
B32: BXT-512_DT-SR | C32: ПК BXT-512 в комплекте с ПО DoorTablet Standard Server Win IoT | D32: =IFERROR(VLOOKUP($B32,Подбор[#All],4,0),"") | E32: =IFERROR(VLOOKUP($B32,Подбор[#All],5,0),"") | F32: =IFERROR(VLOOKUP($B32,Подбор[#All],19,0),"") -> Под заказ
B33: UtiClock_ | C33: Программное обеспечение "Система бронирования переговорных комнат Utinet UtiClock"__ | D33: =IFERROR(VLOOKUP($B33,Подбор[#All],4,0),"") | E33: =IFERROR(VLOOKUP($B33,Подбор[#All],5,0),"")
A34: https://ipmatika.kz/products/qbic-lanneck/ | B34: Lanneck | D34: =IFERROR(VLOOKUP($B34,Подбор[#All],4,0),"") | E34: =IFERROR(VLOOKUP($B34,Подбор[#All],5,0),"") | F34: =IFERROR(VLOOKUP($B34,Подбор[#All],19,0),"")
A35: https://ipmatika.kz/products/qbic-lanneck/TD-1050PRO-B_Lanneck/ | B35: TD-1050PRO-B_Lanneck | C35: TD-1050PRO-B в комплекте с ПО LanneckRoomBooking | D35: =IFERROR(VLOOKUP($B35,Подбор[#All],4,0),"") -> 898150 | E35: =IFERROR(VLOOKUP($B35,Подбор[#All],5,0),"") -> 763427.5 | F35: =IFERROR(VLOOKUP($B35,Подбор[#All],19,0),"")
A36: https://ipmatika.kz/products/qbic-lanneck/TD-1060-Slim-B-Lanneck/ | B36: TD-1060 Slim_B_Lanneck | C36: TD-1060 Slim чёрный в комплекте с ПО LanneckRoomBooking | D36: =IFERROR(VLOOKUP($B36,Подбор[#All],4,0),"") -> 720500 | E36: =IFERROR(VLOOKUP($B36,Подбор[#All],5,0),"") -> 612425 | F36: =IFERROR(VLOOKUP($B36,Подбор[#All],19,0),"")
A37: https://ipmatika.kz/products/qbic-lanneck/TD-1070_Lanneck/ | B37: TD-1070_Lanneck | C37: TD-1070 в комплекте с ПО LanneckRoomBooking | D37: =IFERROR(VLOOKUP($B37,Подбор[#All],4,0),"") -> 1053250 | E37: =IFERROR(VLOOKUP($B37,Подбор[#All],5,0),"") -> 895262.5 | F37: =IFERROR(VLOOKUP($B37,Подбор[#All],19,0),"")
B38: T-Mate | D38: =IFERROR(VLOOKUP($B38,Подбор[#All],4,0),"") | E38: =IFERROR(VLOOKUP($B38,Подбор[#All],5,0),"") | F38: =IFERROR(VLOOKUP($B38,Подбор[#All],19,0),"")
B39: TD-1060 Slim_T-Mate | C39: TD-1060 Slim чёрный в комплекте с ПО T-Mate | D39: =IFERROR(VLOOKUP($B39,Подбор[#All],4,0),"") | E39: =IFERROR(VLOOKUP($B39,Подбор[#All],5,0),"") | F39: =IFERROR(VLOOKUP($B39,Подбор[#All],19,0),"")
B40: TD-1070-L_T-Mate | C40: TD-1070 Lite в комплекте с ПО T-Mate | D40: =IFERROR(VLOOKUP($B40,Подбор[#All],4,0),"") | E40: =IFERROR(VLOOKUP($B40,Подбор[#All],5,0),"") | F40: =IFERROR(VLOOKUP($B40,Подбор[#All],19,0),"")
...

Sheet J&R
A1: Url | B1: Артикул | C1: Описание | D1: РРЦ | E1: Дилер
B2: Средоустойчивые устройства связи
B3: JR100 всепогодные телефоны
B4: а). Взрывозащищенные
A5: https://ipmatika.kz/products/vzryvozashchishchennoe-oborudovanie/J%26R-JREX-FK-SIP/ | B5: JREX101-CB-HB-SIP | C5: JREX101-CB-HB-SIP, клавиатура, маячок, громкоговоритель, PoE, с крышкой | D5: 2236450 | E5: 1565510
A6: https://ipmatika.kz/products/vzryvozashchishchennoe-oborudovanie/J%26R-JREX-CB-SIP/ | B6: JREX101-CB-SIP | C6: JREX101-CB-SIP, PoE, без БП, с крышкой | D6: 1257860 | E6: 880500
A7: https://ipmatika.kz/products/vzryvozashchishchennoe-oborudovanie/J%26R-JREX-FK-SIP/ | B7: JREX101-FK-HB-SIP | C7: JREX101-FK-HB-SIP, клавиатура, маячок, громкоговоритель, PoE, с крышкой | D7: 2351850 | E7: 1646290
A8: https://ipmatika.kz/products/vzryvozashchishchennoe-oborudovanie/J%26R-JREX-FK-SIP/ | B8: JREX101-FK-SIP | C8: JREX101-FK-SIP, клавиатура, PoE, без БП, с крышкой | D8: 1304020 | E8: 912810
A9: https://ipmatika.kz/products/vzryvozashchishchennoe-oborudovanie/J%26R-JREX103-CB-HB-SIP/ | B9: JREX103-CB-HB-SIP | C9: JREX103-CB-HB-SIP, клавиатура, горн, маячок, без крышки, PoE, БП | D9: 2042580 | E9: 1429810
A10: https://ipmatika.kz/products/vzryvozashchishchennoe-oborudovanie/J%26R-JREX103-CB-SIP/ | B10: JREX103-CB-SIP | C10: JREX103-CB-SIP, без крышки, трубка, без клавиатуры и кнопки вызова, PoE, БП | D10: 1151690 | E10: 806180
A11: https://ipmatika.kz/products/vzryvozashchishchennoe-oborudovanie/J%26R-JREX103-CB-SIP/ | B11: JREX103-CB | C11: JREX103-CB, без крышки, трубка, без клавиатуры | D11: 811840 | E11: 568350
A12: https://ipmatika.kz/products/vzryvozashchishchennoe-oborudovanie/J%26R-JREX103-FK-HB-SIP/ | B12: JREX103-FK-HB-SIP | C12: JREX103-FK-HB-SIP, клавиатура, горн, маячок, без крышки, PoE, БП | D12: 2181060 | E12: 1526740
A13: https://ipmatika.kz/products/vzryvozashchishchennoe-oborudovanie/J%26R-JREX103-FK-SIP/ | B13: JREX103-FK-SIP | C13: JREX103-FK-SIP, клавиатура, без крышки, PoE, без БП | D13: 1197850 | E13: 838490
A14: https://ipmatika.kz/products/vzryvozashchishchennoe-oborudovanie/J%26R-JREX-CB-SIP/ | B14: JREX106-A01-CB-SIP | C14: JREX106-A01-CB-SIP, PoE, БП, с крышкой | D14: 1007440 | E14: 705090
A15: https://ipmatika.kz/products/vzryvozashchishchennoe-oborudovanie/J%26R-JREX-CB-SIP/ | B15: JREX106-A01-CB | C15: JREX106-A01-CB, с крышкой, аналоговый | D15: 859730 | E15: 601820
A16: https://ipmatika.kz/products/vzryvozashchishchennoe-oborudovanie/J%26R-JREX-FK-SIP/ | B16: JREX106-A01-SIP | C16: JREX106-A01-SIP, клавиатура, PoE, БП, с крышкой | D16: 1044370 | E16: 731060
... A25: https://ipmatika.kz/products/vzryvozashchishchennoe-oborudovanie/J%26R-JREX103-FK-SIP/ | B25: JREX106 | C25: JREX106, клавиатура, без крышки, аналоговый, взрывозащищенный | D25: 1014950 | E25: 710290
B26: б). Без крышки
A27: https://ipmatika.kz/products/promyshlennye-telefony/jr-jr103-cb-y-sip/ | B27: JR103-CB-4G | C27: JR103-CB-4G, без клавиатуры, БП, без крышки, 1 SIM | D27: 619130 | E27: 433330
A28: https://ipmatika.kz/products/promyshlennye-telefony/jr-jr103-cb-y-sip/ | B28: JR103-CB-L | C28: JR103-CB-L, без клавиатуры, без крышки, маячок, желтый, аналоговый | D28: 530840 | E28: 371590
A29: https://ipmatika.kz/products/promyshlennye-telefony/jr-jr103-cb-y-sip/ | B29: JR103-CB-SIP | C29: JR103-CB-SIP, без клавиатуры, PoE, БП, без крышки | D29: 508340 | E29: 356010
A30: https://ipmatika.kz/products/promyshlennye-telefony/jr-jr103-cb-y-sip/ | B30: JR103-CB | C30: JR103-CB, без клавиатуры, без крышки, аналоговый | D30: 416020 | E30: 291390
A31: https://ipmatika.kz/products/promyshlennye-telefony/jr-jr103-fk-y-sip/ | B31: JR103-FK-4G | C31: JR103-FK-4G, полная клавиатура, БП, без крышки | D31: 656050 | E31: 459290
A32: https://ipmatika.kz/products/promyshlennye-telefony/jr-jr103-fk-y-sip/ | B32: JR103-FK-H-4G | C32: JR103-FK-H-4G, полная клавиатура, громкоговоритель, БП, 1 SIM | D32: 758180 | E32: 530840
A33: https://ipmatika.kz/products/promyshlennye-telefony/jr-jr103-fk-y-h-sip/ | B33: JR103-FK-H-SIP | C33: JR103-FK-H-SIP, полная клавиатура, громкоговоритель, PoE, БП, без крышки | D33: 646820 | E33: 452950
A34: https://ipmatika.kz/products/promyshlennye-telefony/jr-jr103-fk-y-sip/ | B34: JR103-FK-H | C34: JR103-FK-H, полная клавиатура, громкоговоритель, аналоговый | D34: 554500 | E34: 388330
A35: https://ipmatika.kz/https://ipmatika.kz/products/promyshlennye-telefony/jr-jr103-fk-y-hb-sip/ | B35: JR103-FK-HB-4G | C35: JR103-FK-HB-4G, клавиатура, без крышки, горн, маячок, 1 SIM | D35: 785870 | E35: 549890
A36: https://ipmatika.kz/https://ipmatika.kz/products/promyshlennye-telefony/jr-jr103-fk-y-hb-sip/ | B36: JR103-FK-HB-SIP | C36: JR103-FK-HB-SIP, клавиатура, без крышки, горн, маячок, PoE, БП | D36: 665290 | E36: 465640
A37: https://ipmatika.kz/https://ipmatika.kz/products/promyshlennye-telefony/jr-jr103-fk-y-hb-sip/ | B37: JR103-FK-HB | C37: JR103-FK-HB, клавиатура, без крышки, горн, маячок, аналоговый | D37: 572970 | E37: 401020
A38: https://ipmatika.kz/products/promyshlennye-telefony/jr-jr103-fk-y-sip/ | B38: JR103-FK-SIP | C38: JR103-FK-SIP, полная клавиатура, PoE, БП, без крышки | D38: 545270 | E38: 381970
... A49: https://ipmatika.kz/products/promyshlennye-telefony/jr-jr105-fk-y-sip/ | B49: JR105-FK | C49: JR105-FK, дисплей, полная клавиатура, без крышки, желтый, аналоговый | D49: 526810 | E49: 368710
B50: в). С крышкой
A51: https://ipmatika.kz/products/analogovye-telefony/jr-jr101-3b-y/ | B51: JR101-3B-4G | C51: JR101-3B-4G, 3 кнопки, БП, с крышкой | D51: 748950 | E51: 524500
A52: https://ipmatika.kz/products/analogovye-telefony/jr-jr101-3b-y/ | B52: JR101-3B-SIP | C52: JR101-3B-SIP, 3 кнопки, БП, с крышкой | D52: 637590 | E52: 446600
A53: https://ipmatika.kz/products/analogovye-telefony/jr-jr101-3b-y/ | B53: JR101-3B | C53: JR101-3B, 3 кнопки, БП, с крышкой, аналоговый | D53: 545270 | E53: 381970
A54: https://ipmatika.kz/products/promyshlennye-telefony/jr-jr101-cb-y-sip/ | B54: JR101-CB-4G | C54: JR101-CB-4G, без клавиатуры, с крышкой, 1 SIM | D54: 693550 | E54: 485260
A55: 0 | B55: JR101-CB-L-4G | C55: JR101-CB-L-4G, без клавиатуры, маячок, с крышкой, БП, 1 SIM | D55: 730480 | E55: 511220
A56: https://ipmatika.kz/products/promyshlennye-telefony/jr-jr101-%F1b-l-sip/ | B56: JR101-CB-L-SIP | C56: JR101-CB-L-SIP, без клавиатуры, маячок, с крышкой, БП | D56: 619130 | E56: 433330
A57: 0 | B57: JR101-CB-L | C57: JR101-CB-L, без клавиатуры, маячок, с крышкой, аналоговый | D57: 526810 | E57: 368710
A58: https://ipmatika.kz/products/promyshlennye-telefony/jr-jr101-sb-sip/ | B58: JR101-CB-SIP | C58: JR101-CB-SIP, без клавиатуры, PoE, БП, с крышкой | D58: 582200 | E58: 407360
...

Sheet Gigaset
A1: http://gigaset.review.ipmatika.kz/ | D1: http://prices.ipmatika.kz/
A2: Презентация по Gigaset | D2: ЦЕНА
A3: № | B3: Наименование | C3: Артикул | D3: РРЦ | E3: ДИЛЕР
A4: 1 | B4: Gigaset N670 IP PRO, базовая станция, синглсота DECT, Мини-мультисота DECT (до 3 б\с), до 20 трубок, POE | C4: S30852-H2714-R101 | D4: 234230 | E4: 175678.88
A5: 2 | B5: Gigaset N720 DM PRO SYS IM Контроллер | C5: S30852-H2315-R101 | D5: 148720 | E5: 111540
A6: 3 | B6: Gigaset N720 IP PRO SYS IM Базовая станция | C6: S30852-H2314-R101 | D6: 148720 | E6: 111540
A7: 4 | B7: Gigaset N870 IP PRO, базовая станция/DM, микросота DECT, до 60 баз, до 250 трубок, POE | C7: S30852-H2716-R101 | D7: 644650 | E7: 483495.48
A8: 5 | B8: Gigaset N870E IP PRO, базовая станция/DM, съемные внеш. Антенны, микросота DECT, до 60 баз, до 250 трубок, POE | C8: S30852-H2718-R101 | D8: 715480 | E8: 536608.8
A9: 6 | B9: Gigaset SL800H PRO Телефонный аппарат | C9: S30852-H2975-R102 | D9: 197170 | E9: 147875
A10: 7 | B10: Gigaset R700H PRO Телефонный аппарат | C10: S30852-H2976-R102 | D10: 204260 | E10: 153195.12
A11: 8 | B11: Gigaset S700H PRO Телефонный аппарат | C11: S30852-H2974-R102 | D11: 146400 | E11: 109802.68
A12: 9 | B12: Лицензия апгрейда N670 IP PRO до N870 IP PRO | C12: S30852-H2714-X3 | D12: 516510 | E12: 439040
A13: 10 | B13: Лицензия для дект менеджера GIGASET N670 IP PRO | C13: S30852-H2714-X2 | D13: 171650 | E13: 145900
A14: 11 | B14: Лицензия для дект менеджера GIGASET N870 IP PRO | C14: S30852-H2716-X2 | D14: 498060 | E14: 423360
A15: 12 | B15: Лицензия Integrator для N870/N670 IP PRO | C15: S30852-H2716-X1 | D15: 710950 | E15: 604310
... A18: 15 | B18: Крепление на опору для уличного короба ТША511 | C18: КМА1 | D18: 26850 | E18: 21480

Sheet 3CX
K1: http://prices.ipmatika.kz
A2: Годовые лицензии 3CX | I2: =Телефония!G1 -> 0
A3: ОВ | C3: Basic /РРЦ/тг | E3: Pro/РРЦ /тг | G3: Enterprise /РРЦ/тг
C4: =VLOOKUP(B4,[1]Подбор!$A$6:$AD$51,29,0) -> #N/A | E4: =VLOOKUP(D4,[1]Подбор!$A$7:$AD$51,29,0) -> #N/A | G4: =VLOOKUP(F4,[1]Подбор!$A$6:$AD$51,29,0) -> #N/A
A5: 4 | C5: . | D5: 3CXNAP4M12 | E5: =VLOOKUP(D5,Подбор!$A:$S,4,0) -> 242680
